2021-01-03 03:45:52,059 INFO: Microblog startup [in C:\Users\使用者\Documents\python檔案\FLASK ZH MEGA\app\__init__.py:70]
2021-01-03 03:46:30,178 INFO: Microblog startup [in C:\Users\使用者\Documents\python檔案\FLASK ZH MEGA\app\__init__.py:70]
2021-01-03 03:46:37,633 INFO: Microblog startup [in C:\Users\使用者\Documents\python檔案\FLASK ZH MEGA\app\__init__.py:70]
2021-01-03 03:47:19,693 INFO: Microblog startup [in C:\Users\使用者\Documents\python檔案\FLASK ZH MEGA\app\__init__.py:70]
2021-01-03 03:47:47,838 INFO: Microblog startup [in C:\Users\使用者\Documents\python檔案\FLASK ZH MEGA\app\__init__.py:70]
2021-01-03 03:47:57,983 INFO: Microblog startup [in C:\Users\使用者\Documents\python檔案\FLASK ZH MEGA\app\__init__.py:70]
2021-01-03 03:53:04,159 INFO: Microblog startup [in C:\Users\使用者\Documents\python檔案\FLASK ZH MEGA\app\__init__.py:70]
2021-01-03 03:53:31,602 INFO: Microblog startup [in C:\Users\使用者\Documents\python檔案\FLASK ZH MEGA\app\__init__.py:70]
2021-01-03 03:54:15,255 INFO: Microblog startup [in C:\Users\使用者\Documents\python檔案\FLASK ZH MEGA\app\__init__.py:70]
2021-01-03 03:55:20,555 INFO: Microblog startup [in C:\Users\使用者\Documents\python檔案\FLASK ZH MEGA\app\__init__.py:70]
2021-01-03 03:56:04,979 INFO: Microblog startup [in C:\Users\使用者\Documents\python檔案\FLASK ZH MEGA\app\__init__.py:70]
2021-01-03 03:57:30,117 INFO: Microblog startup [in C:\Users\使用者\Documents\python檔案\FLASK ZH MEGA\app\__init__.py:70]
2021-01-03 03:58:27,679 INFO: Microblog startup [in C:\Users\使用者\Documents\python檔案\FLASK ZH MEGA\app\__init__.py:70]
2021-01-03 03:58:57,111 INFO: Microblog startup [in C:\Users\使用者\Documents\python檔案\FLASK ZH MEGA\app\__init__.py:70]
2021-01-03 04:01:10,132 INFO: Microblog startup [in C:\Users\使用者\Documents\python檔案\FLASK ZH MEGA\app\__init__.py:70]
2021-01-03 04:01:50,896 INFO: Microblog startup [in C:\Users\使用者\Documents\python檔案\FLASK ZH MEGA\app\__init__.py:70]
2021-01-03 04:05:09,179 INFO: Microblog startup [in C:\Users\使用者\Documents\python檔案\FLASK ZH MEGA\app\__init__.py:70]
2021-01-03 04:13:01,508 INFO: Microblog startup [in C:\Users\使用者\Documents\python檔案\FLASK ZH MEGA\app\__init__.py:70]
2021-01-03 04:23:32,040 INFO: Microblog startup [in C:\Users\使用者\Documents\python檔案\FLASK ZH MEGA\app\__init__.py:70]
2021-01-03 04:25:39,515 INFO: Microblog startup [in C:\Users\使用者\Documents\python檔案\FLASK ZH MEGA\app\__init__.py:70]
2021-01-03 04:28:27,237 INFO: Microblog startup [in C:\Users\使用者\Documents\python檔案\FLASK ZH MEGA\app\__init__.py:70]
2021-01-03 04:30:11,176 INFO: Microblog startup [in C:\Users\使用者\Documents\python檔案\FLASK ZH MEGA\app\__init__.py:70]
2021-01-03 04:30:20,104 INFO: Microblog startup [in C:\Users\使用者\Documents\python檔案\FLASK ZH MEGA\app\__init__.py:70]
2021-01-03 04:30:25,840 INFO: Microblog startup [in C:\Users\使用者\Documents\python檔案\FLASK ZH MEGA\app\__init__.py:70]
2021-01-03 04:30:54,939 INFO: Microblog startup [in C:\Users\使用者\Documents\python檔案\FLASK ZH MEGA\app\__init__.py:70]
2021-01-03 04:31:14,681 INFO: Microblog startup [in C:\Users\使用者\Documents\python檔案\FLASK ZH MEGA\app\__init__.py:70]
2021-01-03 04:31:25,070 INFO: Microblog startup [in C:\Users\使用者\Documents\python檔案\FLASK ZH MEGA\app\__init__.py:70]
2021-01-03 17:10:46,853 INFO: Microblog startup [in C:\Users\使用者\Documents\python檔案\FLASK ZH MEGA\app\__init__.py:70]
2021-01-03 17:11:30,868 INFO: Microblog startup [in C:\Users\使用者\Documents\python檔案\FLASK ZH MEGA\app\__init__.py:70]
2021-01-03 18:34:37,713 INFO: Microblog startup [in C:\Users\使用者\Documents\python檔案\FLASK ZH MEGA\app\__init__.py:70]
2021-01-03 18:35:44,226 INFO: Microblog startup [in C:\Users\使用者\Documents\python檔案\FLASK ZH MEGA\app\__init__.py:70]
2021-01-03 18:44:43,533 INFO: Microblog startup [in C:\Users\使用者\Documents\python檔案\FLASK ZH MEGA\app\__init__.py:70]
2021-01-03 18:44:51,453 INFO: Microblog startup [in C:\Users\使用者\Documents\python檔案\FLASK ZH MEGA\app\__init__.py:70]
2021-01-04 15:45:05,896 INFO: Microblog startup [in C:\Users\使用者\Documents\python檔案\FLASK ZH MEGA\app\__init__.py:87]
2021-01-04 15:45:10,173 ERROR: Exception on / [GET] [in c:\users\使用者\appdata\local\programs\python\python38\lib\site-packages\flask\app.py:1891]
Traceback (most recent call last):
  File "c:\users\使用者\appdata\local\programs\python\python38\lib\site-packages\flask\app.py", line 2447, in wsgi_app
    response = self.full_dispatch_request()
  File "c:\users\使用者\appdata\local\programs\python\python38\lib\site-packages\flask\app.py", line 1952, in full_dispatch_request
    rv = self.handle_user_exception(e)
  File "c:\users\使用者\appdata\local\programs\python\python38\lib\site-packages\flask\app.py", line 1821, in handle_user_exception
    reraise(exc_type, exc_value, tb)
  File "c:\users\使用者\appdata\local\programs\python\python38\lib\site-packages\flask\_compat.py", line 39, in reraise
    raise value
  File "c:\users\使用者\appdata\local\programs\python\python38\lib\site-packages\flask\app.py", line 1950, in full_dispatch_request
    rv = self.dispatch_request()
  File "c:\users\使用者\appdata\local\programs\python\python38\lib\site-packages\flask\app.py", line 1936, in dispatch_request
    return self.view_functions[rule.endpoint](**req.view_args)
  File "c:\users\使用者\appdata\local\programs\python\python38\lib\site-packages\flask_login\utils.py", line 271, in decorated_view
    return current_app.login_manager.unauthorized()
  File "c:\users\使用者\appdata\local\programs\python\python38\lib\site-packages\flask_login\login_manager.py", line 174, in unauthorized
    redirect_url = make_login_url(login_view, next_url=request.url)
  File "c:\users\使用者\appdata\local\programs\python\python38\lib\site-packages\flask_login\utils.py", line 120, in login_url
    base = expand_login_view(login_view)
  File "c:\users\使用者\appdata\local\programs\python\python38\lib\site-packages\flask_login\utils.py", line 97, in expand_login_view
    return url_for(login_view)
  File "c:\users\使用者\appdata\local\programs\python\python38\lib\site-packages\flask\helpers.py", line 370, in url_for
    return appctx.app.handle_url_build_error(error, endpoint, values)
  File "c:\users\使用者\appdata\local\programs\python\python38\lib\site-packages\flask\app.py", line 2216, in handle_url_build_error
    reraise(exc_type, exc_value, tb)
  File "c:\users\使用者\appdata\local\programs\python\python38\lib\site-packages\flask\_compat.py", line 39, in reraise
    raise value
  File "c:\users\使用者\appdata\local\programs\python\python38\lib\site-packages\flask\helpers.py", line 357, in url_for
    rv = url_adapter.build(
  File "c:\users\使用者\appdata\local\programs\python\python38\lib\site-packages\werkzeug\routing.py", line 2179, in build
    raise BuildError(endpoint, values, method, self)
werkzeug.routing.BuildError: Could not build url for endpoint 'auth.login'. Did you mean 'main.user' instead?
2021-01-04 15:46:09,416 INFO: Microblog startup [in C:\Users\使用者\Documents\python檔案\FLASK ZH MEGA\app\__init__.py:87]
2021-01-04 15:46:11,573 ERROR: Exception on / [GET] [in c:\users\使用者\appdata\local\programs\python\python38\lib\site-packages\flask\app.py:1891]
Traceback (most recent call last):
  File "c:\users\使用者\appdata\local\programs\python\python38\lib\site-packages\flask\app.py", line 2447, in wsgi_app
    response = self.full_dispatch_request()
  File "c:\users\使用者\appdata\local\programs\python\python38\lib\site-packages\flask\app.py", line 1952, in full_dispatch_request
    rv = self.handle_user_exception(e)
  File "c:\users\使用者\appdata\local\programs\python\python38\lib\site-packages\flask\app.py", line 1821, in handle_user_exception
    reraise(exc_type, exc_value, tb)
  File "c:\users\使用者\appdata\local\programs\python\python38\lib\site-packages\flask\_compat.py", line 39, in reraise
    raise value
  File "c:\users\使用者\appdata\local\programs\python\python38\lib\site-packages\flask\app.py", line 1950, in full_dispatch_request
    rv = self.dispatch_request()
  File "c:\users\使用者\appdata\local\programs\python\python38\lib\site-packages\flask\app.py", line 1936, in dispatch_request
    return self.view_functions[rule.endpoint](**req.view_args)
  File "c:\users\使用者\appdata\local\programs\python\python38\lib\site-packages\flask_login\utils.py", line 271, in decorated_view
    return current_app.login_manager.unauthorized()
  File "c:\users\使用者\appdata\local\programs\python\python38\lib\site-packages\flask_login\login_manager.py", line 174, in unauthorized
    redirect_url = make_login_url(login_view, next_url=request.url)
  File "c:\users\使用者\appdata\local\programs\python\python38\lib\site-packages\flask_login\utils.py", line 120, in login_url
    base = expand_login_view(login_view)
  File "c:\users\使用者\appdata\local\programs\python\python38\lib\site-packages\flask_login\utils.py", line 97, in expand_login_view
    return url_for(login_view)
  File "c:\users\使用者\appdata\local\programs\python\python38\lib\site-packages\flask\helpers.py", line 370, in url_for
    return appctx.app.handle_url_build_error(error, endpoint, values)
  File "c:\users\使用者\appdata\local\programs\python\python38\lib\site-packages\flask\app.py", line 2216, in handle_url_build_error
    reraise(exc_type, exc_value, tb)
  File "c:\users\使用者\appdata\local\programs\python\python38\lib\site-packages\flask\_compat.py", line 39, in reraise
    raise value
  File "c:\users\使用者\appdata\local\programs\python\python38\lib\site-packages\flask\helpers.py", line 357, in url_for
    rv = url_adapter.build(
  File "c:\users\使用者\appdata\local\programs\python\python38\lib\site-packages\werkzeug\routing.py", line 2179, in build
    raise BuildError(endpoint, values, method, self)
werkzeug.routing.BuildError: Could not build url for endpoint 'auth.login'. Did you mean 'main.user' instead?
2021-01-04 15:47:11,628 INFO: Microblog startup [in C:\Users\使用者\Documents\python檔案\FLASK ZH MEGA\app\__init__.py:87]
