2021-01-04 16:21:05,137 ERROR: Exception on / [GET] [in c:\users\使用者\appdata\local\programs\python\python38\lib\site-packages\flask\app.py:1891]
Traceback (most recent call last):
  File "c:\users\使用者\appdata\local\programs\python\python38\lib\site-packages\flask\app.py", line 2447, in wsgi_app
    response = self.full_dispatch_request()
  File "c:\users\使用者\appdata\local\programs\python\python38\lib\site-packages\flask\app.py", line 1952, in full_dispatch_request
    rv = self.handle_user_exception(e)
  File "c:\users\使用者\appdata\local\programs\python\python38\lib\site-packages\flask\app.py", line 1821, in handle_user_exception
    reraise(exc_type, exc_value, tb)
  File "c:\users\使用者\appdata\local\programs\python\python38\lib\site-packages\flask\_compat.py", line 39, in reraise
    raise value
  File "c:\users\使用者\appdata\local\programs\python\python38\lib\site-packages\flask\app.py", line 1950, in full_dispatch_request
    rv = self.dispatch_request()
  File "c:\users\使用者\appdata\local\programs\python\python38\lib\site-packages\flask\app.py", line 1936, in dispatch_request
    return self.view_functions[rule.endpoint](**req.view_args)
  File "c:\users\使用者\appdata\local\programs\python\python38\lib\site-packages\flask_login\utils.py", line 271, in decorated_view
    return current_app.login_manager.unauthorized()
  File "c:\users\使用者\appdata\local\programs\python\python38\lib\site-packages\flask_login\login_manager.py", line 174, in unauthorized
    redirect_url = make_login_url(login_view, next_url=request.url)
  File "c:\users\使用者\appdata\local\programs\python\python38\lib\site-packages\flask_login\utils.py", line 120, in login_url
    base = expand_login_view(login_view)
  File "c:\users\使用者\appdata\local\programs\python\python38\lib\site-packages\flask_login\utils.py", line 97, in expand_login_view
    return url_for(login_view)
  File "c:\users\使用者\appdata\local\programs\python\python38\lib\site-packages\flask\helpers.py", line 370, in url_for
    return appctx.app.handle_url_build_error(error, endpoint, values)
  File "c:\users\使用者\appdata\local\programs\python\python38\lib\site-packages\flask\app.py", line 2216, in handle_url_build_error
    reraise(exc_type, exc_value, tb)
  File "c:\users\使用者\appdata\local\programs\python\python38\lib\site-packages\flask\_compat.py", line 39, in reraise
    raise value
  File "c:\users\使用者\appdata\local\programs\python\python38\lib\site-packages\flask\helpers.py", line 357, in url_for
    rv = url_adapter.build(
  File "c:\users\使用者\appdata\local\programs\python\python38\lib\site-packages\werkzeug\routing.py", line 2179, in build
    raise BuildError(endpoint, values, method, self)
werkzeug.routing.BuildError: Could not build url for endpoint 'auth.login'. Did you mean 'main.user' instead?
2021-01-04 16:26:01,343 INFO: Microblog startup [in C:\Users\使用者\Documents\python檔案\FLASK ZH MEGA\app\__init__.py:87]
2021-01-04 16:26:02,645 ERROR: Exception on / [GET] [in c:\users\使用者\appdata\local\programs\python\python38\lib\site-packages\flask\app.py:1891]
Traceback (most recent call last):
  File "c:\users\使用者\appdata\local\programs\python\python38\lib\site-packages\flask\app.py", line 2447, in wsgi_app
    response = self.full_dispatch_request()
  File "c:\users\使用者\appdata\local\programs\python\python38\lib\site-packages\flask\app.py", line 1952, in full_dispatch_request
    rv = self.handle_user_exception(e)
  File "c:\users\使用者\appdata\local\programs\python\python38\lib\site-packages\flask\app.py", line 1821, in handle_user_exception
    reraise(exc_type, exc_value, tb)
  File "c:\users\使用者\appdata\local\programs\python\python38\lib\site-packages\flask\_compat.py", line 39, in reraise
    raise value
  File "c:\users\使用者\appdata\local\programs\python\python38\lib\site-packages\flask\app.py", line 1950, in full_dispatch_request
    rv = self.dispatch_request()
  File "c:\users\使用者\appdata\local\programs\python\python38\lib\site-packages\flask\app.py", line 1936, in dispatch_request
    return self.view_functions[rule.endpoint](**req.view_args)
  File "c:\users\使用者\appdata\local\programs\python\python38\lib\site-packages\flask_login\utils.py", line 271, in decorated_view
    return current_app.login_manager.unauthorized()
  File "c:\users\使用者\appdata\local\programs\python\python38\lib\site-packages\flask_login\login_manager.py", line 174, in unauthorized
    redirect_url = make_login_url(login_view, next_url=request.url)
  File "c:\users\使用者\appdata\local\programs\python\python38\lib\site-packages\flask_login\utils.py", line 120, in login_url
    base = expand_login_view(login_view)
  File "c:\users\使用者\appdata\local\programs\python\python38\lib\site-packages\flask_login\utils.py", line 97, in expand_login_view
    return url_for(login_view)
  File "c:\users\使用者\appdata\local\programs\python\python38\lib\site-packages\flask\helpers.py", line 370, in url_for
    return appctx.app.handle_url_build_error(error, endpoint, values)
  File "c:\users\使用者\appdata\local\programs\python\python38\lib\site-packages\flask\app.py", line 2216, in handle_url_build_error
    reraise(exc_type, exc_value, tb)
  File "c:\users\使用者\appdata\local\programs\python\python38\lib\site-packages\flask\_compat.py", line 39, in reraise
    raise value
  File "c:\users\使用者\appdata\local\programs\python\python38\lib\site-packages\flask\helpers.py", line 357, in url_for
    rv = url_adapter.build(
  File "c:\users\使用者\appdata\local\programs\python\python38\lib\site-packages\werkzeug\routing.py", line 2179, in build
    raise BuildError(endpoint, values, method, self)
werkzeug.routing.BuildError: Could not build url for endpoint 'auth.login'. Did you mean 'main.user' instead?
2021-01-04 16:33:13,204 INFO: Microblog startup [in C:\Users\使用者\Documents\python檔案\FLASK ZH MEGA\app\__init__.py:87]
2021-01-04 16:33:15,075 ERROR: Exception on / [GET] [in c:\users\使用者\appdata\local\programs\python\python38\lib\site-packages\flask\app.py:1891]
Traceback (most recent call last):
  File "c:\users\使用者\appdata\local\programs\python\python38\lib\site-packages\flask\app.py", line 2447, in wsgi_app
    response = self.full_dispatch_request()
  File "c:\users\使用者\appdata\local\programs\python\python38\lib\site-packages\flask\app.py", line 1952, in full_dispatch_request
    rv = self.handle_user_exception(e)
  File "c:\users\使用者\appdata\local\programs\python\python38\lib\site-packages\flask\app.py", line 1821, in handle_user_exception
    reraise(exc_type, exc_value, tb)
  File "c:\users\使用者\appdata\local\programs\python\python38\lib\site-packages\flask\_compat.py", line 39, in reraise
    raise value
  File "c:\users\使用者\appdata\local\programs\python\python38\lib\site-packages\flask\app.py", line 1950, in full_dispatch_request
    rv = self.dispatch_request()
  File "c:\users\使用者\appdata\local\programs\python\python38\lib\site-packages\flask\app.py", line 1936, in dispatch_request
    return self.view_functions[rule.endpoint](**req.view_args)
  File "c:\users\使用者\appdata\local\programs\python\python38\lib\site-packages\flask_login\utils.py", line 271, in decorated_view
    return current_app.login_manager.unauthorized()
  File "c:\users\使用者\appdata\local\programs\python\python38\lib\site-packages\flask_login\login_manager.py", line 174, in unauthorized
    redirect_url = make_login_url(login_view, next_url=request.url)
  File "c:\users\使用者\appdata\local\programs\python\python38\lib\site-packages\flask_login\utils.py", line 120, in login_url
    base = expand_login_view(login_view)
  File "c:\users\使用者\appdata\local\programs\python\python38\lib\site-packages\flask_login\utils.py", line 97, in expand_login_view
    return url_for(login_view)
  File "c:\users\使用者\appdata\local\programs\python\python38\lib\site-packages\flask\helpers.py", line 370, in url_for
    return appctx.app.handle_url_build_error(error, endpoint, values)
  File "c:\users\使用者\appdata\local\programs\python\python38\lib\site-packages\flask\app.py", line 2216, in handle_url_build_error
    reraise(exc_type, exc_value, tb)
  File "c:\users\使用者\appdata\local\programs\python\python38\lib\site-packages\flask\_compat.py", line 39, in reraise
    raise value
  File "c:\users\使用者\appdata\local\programs\python\python38\lib\site-packages\flask\helpers.py", line 357, in url_for
    rv = url_adapter.build(
  File "c:\users\使用者\appdata\local\programs\python\python38\lib\site-packages\werkzeug\routing.py", line 2179, in build
    raise BuildError(endpoint, values, method, self)
werkzeug.routing.BuildError: Could not build url for endpoint 'auth.login'. Did you mean 'main.user' instead?
2021-01-04 16:45:16,698 INFO: Microblog startup [in C:\Users\使用者\Documents\python檔案\FLASK ZH MEGA\app\__init__.py:87]
2021-01-04 16:58:01,729 INFO: Microblog startup [in C:\Users\使用者\Documents\python檔案\FLASK ZH MEGA\app\__init__.py:90]
2021-01-04 17:00:11,474 INFO: Microblog startup [in C:\Users\使用者\Documents\python檔案\FLASK ZH MEGA\app\__init__.py:90]
2021-01-04 17:13:18,786 INFO: Microblog startup [in C:\Users\使用者\Documents\python檔案\FLASK ZH MEGA\app\__init__.py:90]
2021-01-04 17:21:47,741 INFO: Microblog startup [in C:\Users\使用者\Documents\python檔案\FLASK ZH MEGA\app\__init__.py:90]
